<?xml version='1.0' encoding='utf-8'?>
<robot name="franka_hand">
  <link name="fr3_hand">
    <visual name="fr3_hand_visual">
      <geometry>
        <mesh filename="../visual/hand.dae" />
      </geometry>
    </visual>
    <collision name="fr3_hand_collision">
      <geometry>
        <mesh filename="../collision/hand.stl" />
      </geometry>
    </collision>
    <inertial>
      <origin rpy="0 0 0" xyz="-0.0000376 0.0119128 0.0207260" />
      <mass value="0.6544" />
      <inertia ixx="0.00186" ixy="0.0" ixz="0.0" iyy="0.0003" iyz="-2e-05" izz="0.00174" />
    </inertial>
  </link>
  <link name="fr3_hand_tcp" />
  <joint name="fr3_hand_tcp_joint" type="fixed">
    <origin rpy="0 0 0" xyz="0 0 0.1034" />
    <parent link="fr3_hand" />
    <child link="fr3_hand_tcp" />
  </joint>
  <link name="fr3_leftfinger">
    <visual name="fr3_leftfinger_visual">
      <geometry>
        <mesh filename="../visual/finger.dae" />
      </geometry>
    </visual>
    <collision>
      <origin rpy="0 0 0" xyz="0 18.5e-3 11e-3" />
      <geometry>
        <box size="22e-3 15e-3 20e-3" />
      </geometry>
    </collision>
    <collision>
      <origin rpy="0 0 0" xyz="0 6.8e-3 2.2e-3" />
      <geometry>
        <box size="22e-3 8.8e-3 3.8e-3" />
      </geometry>
    </collision>
    <collision>
      <origin rpy="0.5235987755982988 0 0" xyz="0 15.9e-3 28.35e-3" />
      <geometry>
        <box size="17.5e-3 7e-3 23.5e-3" />
      </geometry>
    </collision>
    <collision>
      <origin rpy="0 0 0" xyz="0 7.58e-3 45.25e-3" />
      <geometry>
        <box size="17.5e-3 15.2e-3 18.5e-3" />
      </geometry>
    </collision>
    <inertial>
      <origin rpy="0 0 0" xyz="0 0.0152850 0.0219675" />
      <mass value="0.0291" />
      <inertia ixx="8.49e-06" ixy="0.0" ixz="0.0" iyy="8.53e-06" iyz="-1.06e-06" izz="1.77e-06" />
    </inertial>
  </link>
  <link name="fr3_rightfinger">
    <visual name="fr3_rightfinger_visual">
      <origin rpy="0 0 0" xyz="0 0 0" />
      <geometry>
        <mesh filename="../visual/finger.dae" />
      </geometry>
    </visual>
    <collision>
      <origin rpy="0 0 0" xyz="0 18.5e-3 11e-3" />
      <geometry>
        <box size="22e-3 15e-3 20e-3" />
      </geometry>
    </collision>
    <collision>
      <origin rpy="0 0 0" xyz="0 6.8e-3 2.2e-3" />
      <geometry>
        <box size="22e-3 8.8e-3 3.8e-3" />
      </geometry>
    </collision>
    <collision>
      <origin rpy="-0.5235987755982988 0 3.141592653589793" xyz="0 15.9e-3 28.35e-3" />
      <geometry>
        <box size="17.5e-3 7e-3 23.5e-3" />
      </geometry>
    </collision>
    <collision>
      <origin rpy="0 0 0" xyz="0 7.58e-3 45.25e-3" />
      <geometry>
        <box size="17.5e-3 15.2e-3 18.5e-3" />
      </geometry>
    </collision>
    <inertial>
      <origin rpy="0 0 0" xyz="0 0.0152850 0.0219675" />
      <mass value="0.0291" />
      <inertia ixx="8.49e-06" ixy="0.0" ixz="0.0" iyy="8.53e-06" iyz="-1.06e-06" izz="1.77e-06" />
    </inertial>
  </link>
  <joint name="fr3_finger_joint1" type="prismatic">
    <parent link="fr3_hand" />
    <child link="fr3_leftfinger" />
    <origin rpy="0 0 0" xyz="0 0 0.0584" />
    <axis xyz="0 1 0" />
    <limit effort="100" lower="0.0" upper="0.04" velocity="0.2" />
    <dynamics damping="0.3" />
  </joint>
  <joint name="fr3_finger_joint2" type="prismatic">
    <parent link="fr3_hand" />
    <child link="fr3_rightfinger" />
    <origin rpy="0 0 3.141592653589793" xyz="0 0 0.0584" />
    <axis xyz="0 1 0" />
    <limit effort="100" lower="0.0" upper="0.04" velocity="0.2" />
    <mimic joint="fr3_finger_joint1" />
    <dynamics damping="0.3" />
  </joint>
</robot>